<?xml version="1.0"?>
<robot xmlns:xacro="http://www.ros.org/wiki/xacro" name="okasha_robot">
    <xacro:include filename="inertial_macros.xacro"/>
    <xacro:include filename="chasis.xacro"/>
    <xacro:include filename="wheel.xacro"/>
    <xacro:include filename="lidar.xacro"/>
    <xacro:include filename="camera.xacro"/>

    <xacro:camera_link name="camera"/>
    <xacro:chasis_link name="chasis"/>
    <xacro:lidar_link name="lidar"/>
    <xacro:wheel_link name="wheel_one"/>
    <xacro:wheel_link name="wheel_two"/>
    <xacro:wheel_link name="wheel_three"/>
    <xacro:wheel_link name="wheel_four"/>

    <joint name="chasis_camera" type="fixed">
        <parent link="chasis"/>
        <child link="camera"/>
        <origin xyz="1.05 0.0 -0.1" rpy="0.0 0.0 0.0"/>
    </joint>
    <joint name="chasis_lidar" type="fixed">
        <parent link="chasis"/>
        <child link="lidar"/>
        <origin xyz="0.0 0.0 0.15" rpy="0.0 0.0 0.0"/>
    </joint>
    <joint name="chasis_wheel_one" type="continuous">
        <parent link="chasis"/>
        <child link="wheel_one"/>
        <axis xyz="0.0 1.0 0.0"/>
        <origin xyz="0.5 0.6 0" rpy="0 0 0"/>
    </joint>
    <joint name="chasis_wheel_two" type="continuous">
        <parent link="chasis"/>
        <child link="wheel_two"/>
        <axis xyz="0.0 1.0 0.0"/>
        <origin xyz="0.5 -0.6 0" rpy="0 0 0"/>
    </joint>
    <joint name="chasis_wheel_three" type="continuous">
        <parent link="chasis"/>
        <child link="wheel_three"/>
        <axis xyz="0.0 1.0 0.0"/>
        <origin xyz="-0.5 0.6 0" rpy="0 0 0"/>
    </joint>
    <joint name="chasis_wheel_four" type="continuous">
        <parent link="chasis"/>
        <child link="wheel_four"/>
        <axis xyz="0.0 1.0 0.0"/>
        <origin xyz="-0.5 -0.6 0" rpy="0 0 0"/>
    </joint>

    
</robot>